Workbook

Sheet Data_Scores
A1: Depth | B1: Vegetation | C1: Profile | D1: Identifier | E1: ID_code | F1: Sand | G1: Silt | H1: Clay | I1: pH | J1: CTC | K1: N | L1: P | M1: SB | N1: C | O1: BD_Benites_2007 | P1: score_pH | Q1: score_CTC | R1: score_N | S1: score_P | T1: score_SB | U1: score_C | V1: score_BD
A2: P20 | B2: SSF | C2: S102 | D2: S102 | E2: S39 | F2: 848 | G2: 21 | H2: 50 | I2: 3.88 | J2: 57.3 | K2: 0.06 | L2: 5.5 | M2: 4.6 | N2: 0.79 | O2: 1.5616 | P2: {=I2/MAX(IF($A$2:$A$146=A2,$I$2:$I$146))} -> 0.77755511 | Q2: {=J2/MAX(IF($A$2:$A$146=A2,$J$2:$J$146))} -> 0.7135741 | R2: {=K2/MAX(IF($A$2:$A$146=A2,$K$2:$K$146))} -> 0.6 | S2: {=L2/MAX(IF($A$2:$A$146=A2,$L$2:$L$146))} -> 0.6875 | T2: {=M2/MAX(IF($A$2:$A$146=A2,$M$2:$M$146))} -> 0.13180516 | U2: {=N2/MAX(IF($A$2:$A$146=A2,$N$2:$N$146))} -> 0.6171875 | V2: {=MIN(IF($A$2:$A$146=A2,$O$2:$O$146))/O2} -> 0.96820569
A3: P40 | B3: SSF | C3: S102 | D3: S102,1 | E3: S73 | F3: 848 | G3: 33 | H3: 125 | I3: 3.9 | J3: 57.9 | K3: 0.05 | L3: 6 | M3: 4.1 | N3: 0.7 | O3: 1.52125 | P3: {=I3/MAX(IF($A$2:$A$146=A3,$I$2:$I$146))} -> 0.80082136 | Q3: {=J3/MAX(IF($A$2:$A$146=A3,$J$2:$J$146))} -> 0.92050874 | R3: {=K3/MAX(IF($A$2:$A$146=A3,$K$2:$K$146))} -> 0.625 | S3: {=L3/MAX(IF($A$2:$A$146=A3,$L$2:$L$146))} -> 1 | T3: {=M3/MAX(IF($A$2:$A$146=A3,$M$2:$M$146))} -> 0.16803279 | U3: {=N3/MAX(IF($A$2:$A$146=A3,$N$2:$N$146))} -> 0.61403509 | V3: {=MIN(IF($A$2:$A$146=A3,$O$2:$O$146))/O3} -> 0.98211997
A4: P60 | B4: SSF | C4: S102 | D4: S102,2 | E4: S107 | F4: 848 | G4: 17 | H4: 177 | I4: 3.83 | J4: 52.9 | K4: 0.05 | L4: 4.2 | M4: 3.5 | N4: 0.66 | O4: 1.49115 | P4: {=I4/MAX(IF($A$2:$A$146=A4,$I$2:$I$146))} -> 0.82365591 | Q4: {=J4/MAX(IF($A$2:$A$146=A4,$J$2:$J$146))} -> 1 | R4: {=K4/MAX(IF($A$2:$A$146=A4,$K$2:$K$146))} -> 1 | S4: {=L4/MAX(IF($A$2:$A$146=A4,$L$2:$L$146))} -> 0.14532872 | T4: {=M4/MAX(IF($A$2:$A$146=A4,$M$2:$M$146))} -> 0.21212121 | U4: {=N4/MAX(IF($A$2:$A$146=A4,$N$2:$N$146))} -> 1 | V4: {=MIN(IF($A$2:$A$146=A4,$O$2:$O$146))/O4} -> 0.98990712
A5: P80 | B5: SSF | C5: S102 | D5: S102,3 | E5: S141 | F5: 848 | G5: 25 | H5: 176 | I5: 3.81 | J5: 52.9 | K5: 0.04 | L5: 0.9 | M5: 2.4 | N5: 0.52 | O5: 1.4848 | P5: {=I5/MAX(IF($A$2:$A$146=A5,$I$2:$I$146))} -> 0.83006536 | Q5: {=J5/MAX(IF($A$2:$A$146=A5,$J$2:$J$146))} -> 0.54312115 | R5: {=K5/MAX(IF($A$2:$A$146=A5,$K$2:$K$146))} -> 1 | S5: {=L5/MAX(IF($A$2:$A$146=A5,$L$2:$L$146))} -> 0.052023121 | T5: {=M5/MAX(IF($A$2:$A$146=A5,$M$2:$M$146))} -> 0.13872832 | U5: {=N5/MAX(IF($A$2:$A$146=A5,$N$2:$N$146))} -> 0.96296296 | V5: {=MIN(IF($A$2:$A$146=A5,$O$2:$O$146))/O5} -> 0.99400593
A6: P100 | B6: SSF | C6: S102 | D6: S102,4 | E6: S175 | F6: 848 | G6: 27 | H6: 176 | I6: 3.84 | J6: 49.8 | K6: 0.03 | L6: 5.5 | M6: 2.4 | N6: 0.4 | O6: 1.486 | P6: {=I6/MAX(IF($A$2:$A$146=A6,$I$2:$I$146))} -> 0.89095128 | Q6: {=J6/MAX(IF($A$2:$A$146=A6,$J$2:$J$146))} -> 1 | R6: {=K6/MAX(IF($A$2:$A$146=A6,$K$2:$K$146))} -> 0.75 | S6: {=L6/MAX(IF($A$2:$A$146=A6,$L$2:$L$146))} -> 0.94827586 | T6: {=M6/MAX(IF($A$2:$A$146=A6,$M$2:$M$146))} -> 0.15384615 | U6: {=N6/MAX(IF($A$2:$A$146=A6,$N$2:$N$146))} -> 0.81632653 | V6: {=MIN(IF($A$2:$A$146=A6,$O$2:$O$146))/O6} -> 1
A7: P20 | B7: SSF | C7: S31 | D7: S31 | E7: S11 | F7: 881 | G7: 18 | H7: 101 | I7: 4.94 | J7: 61.7 | K7: 0.07 | L7: 8 | M7: 34.9 | N7: 0.98 | O7: 1.76145 | P7: {=I7/MAX(IF($A$2:$A$146=A7,$I$2:$I$146))} -> 0.98997996 | Q7: {=J7/MAX(IF($A$2:$A$146=A7,$J$2:$J$146))} -> 0.76836862 | R7: {=K7/MAX(IF($A$2:$A$146=A7,$K$2:$K$146))} -> 0.7 | S7: {=L7/MAX(IF($A$2:$A$146=A7,$L$2:$L$146))} -> 1 | T7: {=M7/MAX(IF($A$2:$A$146=A7,$M$2:$M$146))} -> 1 | U7: {=N7/MAX(IF($A$2:$A$146=A7,$N$2:$N$146))} -> 0.765625 | V7: {=MIN(IF($A$2:$A$146=A7,$O$2:$O$146))/O7} -> 0.85835533
A8: P40 | B8: SSF | C8: S31 | D8: S31,1 | E8: S45 | F8: 872 | G8: 15 | H8: 113 | I8: 4.75 | J8: 54.2 | K8: 0.06 | L8: 5.1 | M8: 24.4 | N8: 0.79 | O8: 1.6786 | P8: {=I8/MAX(IF($A$2:$A$146=A8,$I$2:$I$146))} -> 0.97535934 | Q8: {=J8/MAX(IF($A$2:$A$146=A8,$J$2:$J$146))} -> 0.86168521 | R8: {=K8/MAX(IF($A$2:$A$146=A8,$K$2:$K$146))} -> 0.75 | S8: {=L8/MAX(IF($A$2:$A$146=A8,$L$2:$L$146))} -> 0.85 | T8: {=M8/MAX(IF($A$2:$A$146=A8,$M$2:$M$146))} -> 1 | U8: {=N8/MAX(IF($A$2:$A$146=A8,$N$2:$N$146))} -> 0.69298246 | V8: {=MIN(IF($A$2:$A$146=A8,$O$2:$O$146))/O8} -> 0.89005719
A9: P60 | B9: SSF | C9: S31 | D9: S31,2 | E9: S79 | F9: 860 | G9: 27 | H9: 112 | I9: 4.65 | J9: 35.6 | K9: 0.03 | L9: 4 | M9: 15.2 | N9: 0.4 | O9: 1.614 | P9: {=I9/MAX(IF($A$2:$A$146=A9,$I$2:$I$146))} -> 1 | Q9: {=J9/MAX(IF($A$2:$A$146=A9,$J$2:$J$146))} -> 0.67296786 | R9: {=K9/MAX(IF($A$2:$A$146=A9,$K$2:$K$146))} -> 0.6 | S9: {=L9/MAX(IF($A$2:$A$146=A9,$L$2:$L$146))} -> 0.1384083 | T9: {=M9/MAX(IF($A$2:$A$146=A9,$M$2:$M$146))} -> 0.92121212 | U9: {=N9/MAX(IF($A$2:$A$146=A9,$N$2:$N$146))} -> 0.60606061 | V9: {=MIN(IF($A$2:$A$146=A9,$O$2:$O$146))/O9} -> 0.9145601
A10: P80 | B10: SSF | C10: S31 | D10: S31,3 | E10: S113 | F10: 888 | G10: 10 | H10: 101 | I10: 4.59 | J10: 32.4 | K10: 0.02 | L10: 6.6 | M10: 14.2 | N10: 0.27 | O10: 1.6133 | P10: {=I10/MAX(IF($A$2:$A$146=A10,$I$2:$I$146))} -> 1 | Q10: {=J10/MAX(IF($A$2:$A$146=A10,$J$2:$J$146))} -> 0.33264887 | R10: {=K10/MAX(IF($A$2:$A$146=A10,$K$2:$K$146))} -> 0.5 | S10: {=L10/MAX(IF($A$2:$A$146=A10,$L$2:$L$146))} -> 0.38150289 | T10: {=M10/MAX(IF($A$2:$A$146=A10,$M$2:$M$146))} -> 0.82080925 | U10: {=N10/MAX(IF($A$2:$A$146=A10,$N$2:$N$146))} -> 0.5 | V10: {=MIN(IF($A$2:$A$146=A10,$O$2:$O$146))/O10} -> 0.91483295
A11: P100 | B11: SSF | C11: S31 | D11: S31,4 | E11: S147 | F11: 876 | G11: 24 | H11: 100 | I11: 4.31 | J11: 31.7 | K11: 0.02 | L11: 0.9 | M11: 11.9 | N11: 0.31 | O11: 1.59615 | P11: {=I11/MAX(IF($A$2:$A$146=A11,$I$2:$I$146))} -> 1 | Q11: {=J11/MAX(IF($A$2:$A$146=A11,$J$2:$J$146))} -> 0.63654618 | R11: {=K11/MAX(IF($A$2:$A$146=A11,$K$2:$K$146))} -> 0.5 | S11: {=L11/MAX(IF($A$2:$A$146=A11,$L$2:$L$146))} -> 0.15517241 | T11: {=M11/MAX(IF($A$2:$A$146=A11,$M$2:$M$146))} -> 0.76282051 | U11: {=N11/MAX(IF($A$2:$A$146=A11,$N$2:$N$146))} -> 0.63265306 | V11: {=MIN(IF($A$2:$A$146=A11,$O$2:$O$146))/O11} -> 0.9309902
A12: P20 | B12: SSF | C12: S71 | D12: S71 | E12: S28 | F12: 859 | G12: 14 | H12: 127 | I12: 4.47 | J12: 60.1 | K12: 0.1 | L12: 3.5 | M12: 16.1 | N12: 1.28 | O12: 1.60445 | P12: {=I12/MAX(IF($A$2:$A$146=A12,$I$2:$I$146))} -> 0.89579158 | Q12: {=J12/MAX(IF($A$2:$A$146=A12,$J$2:$J$146))} -> 0.74844334 | R12: {=K12/MAX(IF($A$2:$A$146=A12,$K$2:$K$146))} -> 1 | S12: {=L12/MAX(IF($A$2:$A$146=A12,$L$2:$L$146))} -> 0.4375 | T12: {=M12/MAX(IF($A$2:$A$146=A12,$M$2:$M$146))} -> 0.46131805 | U12: {=N12/MAX(IF($A$2:$A$146=A12,$N$2:$N$146))} -> 1 | V12: {=MIN(IF($A$2:$A$146=A12,$O$2:$O$146))/O12} -> 0.94234785
A13: P40 | B13: SSF | C13: S71 | D13: S71,1 | E13: S62 | F13: 825 | G13: 24 | H13: 151 | I13: 4.41 | J13: 51.1 | K13: 0.07 | L13: 2.6 | M13: 10.6 | N13: 0.92 | O13: 1.5548 | P13: {=I13/MAX(IF($A$2:$A$146=A13,$I$2:$I$146))} -> 0.90554415 | Q13: {=J13/MAX(IF($A$2:$A$146=A13,$J$2:$J$146))} -> 0.81240064 | R13: {=K13/MAX(IF($A$2:$A$146=A13,$K$2:$K$146))} -> 0.875 | S13: {=L13/MAX(IF($A$2:$A$146=A13,$L$2:$L$146))} -> 0.43333333 | T13: {=M13/MAX(IF($A$2:$A$146=A13,$M$2:$M$146))} -> 0.43442623 | U13: {=N13/MAX(IF($A$2:$A$146=A13,$N$2:$N$146))} -> 0.80701754 | V13: {=MIN(IF($A$2:$A$146=A13,$O$2:$O$146))/O13} -> 0.96092745
... A146: P100 | B146: DA | C146: S65 | D146: S65,4 | E146: S163 | F146: 854 | G146: 20 | H146: 126 | I146: 4.01 | J146: 28.9 | K146: 0.02 | L146: 3.1 | M146: 2.6 | N146: 0.23 | O146: 1.5142 | P146: {=I146/MAX(IF($A$2:$A$146=A146,$I$2:$I$146))} -> 0.93039443 | Q146: {=J146/MAX(IF($A$2:$A$146=A146,$J$2:$J$146))} -> 0.58032129 | R146: {=K146/MAX(IF($A$2:$A$146=A146,$K$2:$K$146))} -> 0.5 | S146: {=L146/MAX(IF($A$2:$A$146=A146,$L$2:$L$146))} -> 0.53448276 | T146: {=M146/MAX(IF($A$2:$A$146=A146,$M$2:$M$146))} -> 0.16666667 | U146: {=N146/MAX(IF($A$2:$A$146=A146,$N$2:$N$146))} -> 0.46938776 | V146: {=MIN(IF($A$2:$A$146=A146,$O$2:$O$146))/O146} -> 0.9813763

Sheet Weights
A1: Component | B1: Weight I | C1: Soil Function | D1: Weight II | E1: Indicator | F1: Weight III
A2: Physical | B2: 0.33 | C2: Support root growth | D2: 1 | E2: BD | F2: 1
A3: Biological | B3: 0.33 | C3: Sustain biological activity | D3: 1 | E3: C | F3: 1
A4: Chemical | B4: 0.33 | C4: Soil acidity regulation | D4: 0.33 | E4: pH | F4: 1
C5: Nutrient storage | D5: 0.33 | E5: CTC | F5: 1
C6: Nutrient availability | D6: 0.33 | E6: N | F6: 0.33
E7: P | F7: 0.33
E8: SB | F8: 0.33

Sheet SHI_Results
A1: Depth | B1: Vegetation | C1: Profile | D1: Identifier | E1: SHI_Physical | F1: SHI_Biological | G1: SHI_Chem_pH | H1: SHI_Chem_CTC | I1: SHI_Chem_Navail | J1: SHI_Chemical | K1: SHI_Layer | L1: Overall_SHI
A2: P20 | B2: SSF | C2: S102 | D2: S102 | E2: =Data_Scores!V2*0.33 -> 0.31950788 | F2: =Data_Scores!U2*0.33 -> 0.20367188 | G2: =Data_Scores!P2*0.33*0.33 -> 0.084675751 | H2: =Data_Scores!Q2*0.33*0.33 -> 0.077708219 | I2: =(Data_Scores!R2+Data_Scores!S2+Data_Scores!T2)*0.33*0.33*0.33 -> 0.051005569 | J2: =G2+H2+I2 -> 0.21338954 | K2: =E2+F2+J2 -> 0.73656929 | L2: =(K2+K3+K4+K5+K6)*0.2 -> 0.8258483
A3: P40 | B3: SSF | C3: S102 | D3: S102,1 | E3: =Data_Scores!V3*0.33 -> 0.32409959 | F3: =Data_Scores!U3*0.33 -> 0.20263158 | G3: =Data_Scores!P3*0.33*0.33 -> 0.087209446 | H3: =Data_Scores!Q3*0.33*0.33 -> 0.1002434 | I3: =(Data_Scores!R3+Data_Scores!S3+Data_Scores!T3)*0.33*0.33*0.33 -> 0.064436219 | J3: =G3+H3+I3 -> 0.25188907 | K3: =E3+F3+J3 -> 0.77862024
A4: P60 | B4: SSF | C4: S102 | D4: S102,2 | E4: =Data_Scores!V4*0.33 -> 0.32666935 | F4: =Data_Scores!U4*0.33 -> 0.33 | G4: =Data_Scores!P4*0.33*0.33 -> 0.089696129 | H4: =Data_Scores!Q4*0.33*0.33 -> 0.1089 | I4: =(Data_Scores!R4+Data_Scores!S4+Data_Scores!T4)*0.33*0.33*0.33 -> 0.048782678 | J4: =G4+H4+I4 -> 0.24737881 | K4: =E4+F4+J4 -> 0.90404816
A5: P80 | B5: SSF | C5: S102 | D5: S102,3 | E5: =Data_Scores!V5*0.33 -> 0.32802196 | F5: =Data_Scores!U5*0.33 -> 0.31777778 | G5: =Data_Scores!P5*0.33*0.33 -> 0.090394118 | H5: =Data_Scores!Q5*0.33*0.33 -> 0.059145893 | I5: =(Data_Scores!R5+Data_Scores!S5+Data_Scores!T5)*0.33*0.33*0.33 -> 0.042792035 | J5: =G5+H5+I5 -> 0.19233205 | K5: =E5+F5+J5 -> 0.83813178
A6: P100 | B6: SSF | C6: S102 | D6: S102,4 | E6: =Data_Scores!V6*0.33 -> 0.33 | F6: =Data_Scores!U6*0.33 -> 0.26938776 | G6: =Data_Scores!P6*0.33*0.33 -> 0.097024594 | H6: =Data_Scores!Q6*0.33*0.33 -> 0.1089 | I6: =(Data_Scores!R6+Data_Scores!S6+Data_Scores!T6)*0.33*0.33*0.33 -> 0.066559709 | J6: =G6+H6+I6 -> 0.2724843 | K6: =E6+F6+J6 -> 0.87187206
A7: P20 | B7: SSF | C7: S31 | D7: S31 | E7: =Data_Scores!V7*0.33 -> 0.28325726 | F7: =Data_Scores!U7*0.33 -> 0.25265625 | G7: =Data_Scores!P7*0.33*0.33 -> 0.10780882 | H7: =Data_Scores!Q7*0.33*0.33 -> 0.083675342 | I7: =(Data_Scores!R7+Data_Scores!S7+Data_Scores!T7)*0.33*0.33*0.33 -> 0.0970299 | J7: =G7+H7+I7 -> 0.28851406 | K7: =E7+F7+J7 -> 0.82442757 | L7: =(K7+K8+K9+K10+K11)*0.2 -> 0.76046614
A8: P40 | B8: SSF | C8: S31 | D8: S31,1 | E8: =Data_Scores!V8*0.33 -> 0.29371887 | F8: =Data_Scores!U8*0.33 -> 0.22868421 | G8: =Data_Scores!P8*0.33*0.33 -> 0.10621663 | H8: =Data_Scores!Q8*0.33*0.33 -> 0.09383752 | I8: =(Data_Scores!R8+Data_Scores!S8+Data_Scores!T8)*0.33*0.33*0.33 -> 0.0934362 | J8: =G8+H8+I8 -> 0.29349035 | K8: =E8+F8+J8 -> 0.81589344
A9: P60 | B9: SSF | C9: S31 | D9: S31,2 | E9: =Data_Scores!V9*0.33 -> 0.30180483 | F9: =Data_Scores!U9*0.33 -> 0.2 | G9: =Data_Scores!P9*0.33*0.33 -> 0.1089 | H9: =Data_Scores!Q9*0.33*0.33 -> 0.0732862 | I9: =(Data_Scores!R9+Data_Scores!S9+Data_Scores!T9)*0.33*0.33*0.33 -> 0.059641779 | J9: =G9+H9+I9 -> 0.24182798 | K9: =E9+F9+J9 -> 0.74363281
A10: P80 | B10: SSF | C10: S31 | D10: S31,3 | E10: =Data_Scores!V10*0.33 -> 0.30189487 | F10: =Data_Scores!U10*0.33 -> 0.165 | G10: =Data_Scores!P10*0.33*0.33 -> 0.1089 | H10: =Data_Scores!Q10*0.33*0.33 -> 0.036225462 | I10: =(Data_Scores!R10+Data_Scores!S10+Data_Scores!T10)*0.33*0.33*0.33 -> 0.061175991 | J10: =G10+H10+I10 -> 0.20630145 | K10: =E10+F10+J10 -> 0.67319633
A11: P100 | B11: SSF | C11: S31 | D11: S31,4 | E11: =Data_Scores!V11*0.33 -> 0.30722676 | F11: =Data_Scores!U11*0.33 -> 0.20877551 | G11: =Data_Scores!P11*0.33*0.33 -> 0.1089 | H11: =Data_Scores!Q11*0.33*0.33 -> 0.06931988 | I11: =(Data_Scores!R11+Data_Scores!S11+Data_Scores!T11)*0.33*0.33*0.33 -> 0.050958412 | J11: =G11+H11+I11 -> 0.22917829 | K11: =E11+F11+J11 -> 0.74518057
A12: P20 | B12: SSF | C12: S71 | D12: S71 | E12: =Data_Scores!V12*0.33 -> 0.31097479 | F12: =Data_Scores!U12*0.33 -> 0.33 | G12: =Data_Scores!P12*0.33*0.33 -> 0.097551703 | H12: =Data_Scores!Q12*0.33*0.33 -> 0.081505479 | I12: =(Data_Scores!R12+Data_Scores!S12+Data_Scores!T12)*0.33*0.33*0.33 -> 0.068237824 | J12: =G12+H12+I12 -> 0.24729501 | K12: =E12+F12+J12 -> 0.8882698 | L12: =(K12+K13+K14+K15+K16)*0.2 -> 0.85433484
A13: P40 | B13: SSF | C13: S71 | D13: S71,1 | E13: =Data_Scores!V13*0.33 -> 0.31710606 | F13: =Data_Scores!U13*0.33 -> 0.26631579 | G13: =Data_Scores!P13*0.33*0.33 -> 0.098613758 | H13: =Data_Scores!Q13*0.33*0.33 -> 0.088470429 | I13: =(Data_Scores!R13+Data_Scores!S13+Data_Scores!T13)*0.33*0.33*0.33 -> 0.06262955 | J13: =G13+H13+I13 -> 0.24971374 | K13: =E13+F13+J13 -> 0.83313559
A14: P60 | B14: SSF | C14: S71 | D14: S71,2 | E14: =Data_Scores!V14*0.33 -> 0.31215187 | F14: =Data_Scores!U14*0.33 -> 0.275 | G14: =Data_Scores!P14*0.33*0.33 -> 0.10117161 | H14: =Data_Scores!Q14*0.33*0.33 -> 0.09078431 | I14: =(Data_Scores!R14+Data_Scores!S14+Data_Scores!T14)*0.33*0.33*0.33 -> 0.071642635 | J14: =G14+H14+I14 -> 0.26359856 | K14: =E14+F14+J14 -> 0.85075043
A15: P80 | B15: SSF | C15: S71 | D15: S71,3 | E15: =Data_Scores!V15*0.33 -> 0.31411241 | F15: =Data_Scores!U15*0.33 -> 0.25666667 | G15: =Data_Scores!P15*0.33*0.33 -> 0.099647059 | H15: =Data_Scores!Q15*0.33*0.33 -> 0.047294353 | I15: =(Data_Scores!R15+Data_Scores!S15+Data_Scores!T15)*0.33*0.33*0.33 -> 0.056502104 | J15: =G15+H15+I15 -> 0.20344352 | K15: =E15+F15+J15 -> 0.77422259
A16: P100 | B16: SSF | C16: S71 | D16: S71,4 | E16: =Data_Scores!V16*0.33 -> 0.31472948 | F16: =Data_Scores!U16*0.33 -> 0.33 | G16: =Data_Scores!P16*0.33*0.33 -> 0.10182529 | H16: =Data_Scores!Q16*0.33*0.33 -> 0.09403012 | I16: =(Data_Scores!R16+Data_Scores!S16+Data_Scores!T16)*0.33*0.33*0.33 -> 0.084710912 | J16: =G16+H16+I16 -> 0.28056632 | K16: =E16+F16+J16 -> 0.9252958
A17: P20 | B17: SSF | C17: S72 | D17: S72 | E17: =Data_Scores!V17*0.33 -> 0.30650459 | F17: =Data_Scores!U17*0.33 -> 0.10054687 | G17: =Data_Scores!P17*0.33*0.33 -> 0.091222846 | H17: =Data_Scores!Q17*0.33*0.33 -> 0.0495 | I17: =(Data_Scores!R17+Data_Scores!S17+Data_Scores!T17)*0.33*0.33*0.33 -> 0.039786841 | J17: =G17+H17+I17 -> 0.18050969 | K17: =E17+F17+J17 -> 0.58756115 | L17: =(K17+K18+K19+K20+K21)*0.2 -> 0.60700355
A18: P40 | B18: SSF | C18: S72 | D18: S72,1 | E18: =Data_Scores!V18*0.33 -> 0.31496886 | F18: =Data_Scores!U18*0.33 -> 0.083947368 | G18: =Data_Scores!P18*0.33*0.33 -> 0.091458111 | H18: =Data_Scores!Q18*0.33*0.33 -> 0.051420191 | I18: =(Data_Scores!R18+Data_Scores!S18+Data_Scores!T18)*0.33*0.33*0.33 -> 0.031444875 | J18: =G18+H18+I18 -> 0.17432318 | K18: =E18+F18+J18 -> 0.5732394
A19: P60 | B19: SSF | C19: S72 | D19: S72,2 | E19: =Data_Scores!V19*0.33 -> 0.3132358 | F19: =Data_Scores!U19*0.33 -> 0.095 | G19: =Data_Scores!P19*0.33*0.33 -> 0.095550968 | H19: =Data_Scores!Q19*0.33*0.33 -> 0.055582231 | I19: =(Data_Scores!R19+Data_Scores!S19+Data_Scores!T19)*0.33*0.33*0.33 -> 0.0603306 | J19: =G19+H19+I19 -> 0.2114638 | K19: =E19+F19+J19 -> 0.6196996
A20: P80 | B20: SSF | C20: S72 | D20: S72,3 | E20: =Data_Scores!V20*0.33 -> 0.31446733 | F20: =Data_Scores!U20*0.33 -> 0.13444444 | G20: =Data_Scores!P20*0.33*0.33 -> 0.094901961 | H20: =Data_Scores!Q20*0.33*0.33 -> 0.029069815 | I20: =(Data_Scores!R20+Data_Scores!S20+Data_Scores!T20)*0.33*0.33*0.33 -> 0.029601286 | J20: =G20+H20+I20 -> 0.15357306 | K20: =E20+F20+J20 -> 0.60248484
A21: P100 | B21: SSF | C21: S72 | D21: S72,4 | E21: =Data_Scores!V21*0.33 -> 0.31988258 | F21: =Data_Scores!U21*0.33 -> 0.13469388 | G21: =Data_Scores!P21*0.33*0.33 -> 0.10561531 | H21: =Data_Scores!Q21*0.33*0.33 -> 0.058604819 | I21: =(Data_Scores!R21+Data_Scores!S21+Data_Scores!T21)*0.33*0.33*0.33 -> 0.033236164 | J21: =G21+H21+I21 -> 0.1974563 | K21: =E21+F21+J21 -> 0.65203276
A22: P20 | B22: SSF | C22: S81 | D22: S81 | E22: =Data_Scores!V22*0.33 -> 0.28452526 | F22: =Data_Scores!U22*0.33 -> 0.268125 | G22: =Data_Scores!P22*0.33*0.33 -> 0.1089 | H22: =Data_Scores!Q22*0.33*0.33 -> 0.078928767 | I22: =(Data_Scores!R22+Data_Scores!S22+Data_Scores!T22)*0.33*0.33*0.33 -> 0.089308336 | J22: =G22+H22+I22 -> 0.2771371 | K22: =E22+F22+J22 -> 0.82978737 | L22: =(K22+K23+K24+K25+K26)*0.2 -> 0.79969089
A23: P40 | B23: SSF | C23: S81 | D23: S81,1 | E23: =Data_Scores!V23*0.33 -> 0.293544 | F23: =Data_Scores!U23*0.33 -> 0.15631579 | G23: =Data_Scores!P23*0.33*0.33 -> 0.1089 | H23: =Data_Scores!Q23*0.33*0.33 -> 0.080679491 | I23: =(Data_Scores!R23+Data_Scores!S23+Data_Scores!T23)*0.33*0.33*0.33 -> 0.067087309 | J23: =G23+H23+I23 -> 0.2566668 | K23: =E23+F23+J23 -> 0.70652659
A24: P60 | B24: SSF | C24: S81 | D24: S81,2 | E24: =Data_Scores!V24*0.33 -> 0.30138469 | F24: =Data_Scores!U24*0.33 -> 0.2 | G24: =Data_Scores!P24*0.33*0.33 -> 0.10210839 | H24: =Data_Scores!Q24*0.33*0.33 -> 0.084196786 | I24: =(Data_Scores!R24+Data_Scores!S24+Data_Scores!T24)*0.33*0.33*0.33 -> 0.061602733 | J24: =G24+H24+I24 -> 0.24790791 | K24: =E24+F24+J24 -> 0.74929259
A25: P80 | B25: SSF | C25: S81 | D25: S81,3 | E25: =Data_Scores!V25*0.33 -> 0.30022931 | F25: =Data_Scores!U25*0.33 -> 0.275 | G25: =Data_Scores!P25*0.33*0.33 -> 0.10296863 | H25: =Data_Scores!Q25*0.33*0.33 -> 0.048412423 | I25: =(Data_Scores!R25+Data_Scores!S25+Data_Scores!T25)*0.33*0.33*0.33 -> 0.07685948 | J25: =G25+H25+I25 -> 0.22824053 | K25: =E25+F25+J25 -> 0.80346984
A26: P100 | B26: SSF | C26: S81 | D26: S81,4 | E26: =Data_Scores!V26*0.33 -> 0.30706324 | F26: =Data_Scores!U26*0.33 -> 0.30306122 | G26: =Data_Scores!P26*0.33*0.33 -> 0.10207796 | H26: =Data_Scores!Q26*0.33*0.33 -> 0.099278313 | I26: =(Data_Scores!R26+Data_Scores!S26+Data_Scores!T26)*0.33*0.33*0.33 -> 0.097897345 | J26: =G26+H26+I26 -> 0.29925362 | K26: =E26+F26+J26 -> 0.90937808
A27: P20 | B27: SSF | C27: S82 | D27: S82 | E27: =Data_Scores!V27*0.33 -> 0.31198593 | F27: =Data_Scores!U27*0.33 -> 0.29648438 | G27: =Data_Scores!P27*0.33*0.33 -> 0.091441082 | H27: =Data_Scores!Q27*0.33*0.33 -> 0.086387671 | I27: =(Data_Scores!R27+Data_Scores!S27+Data_Scores!T27)*0.33*0.33*0.33 -> 0.054497585 | J27: =G27+H27+I27 -> 0.23232634 | K27: =E27+F27+J27 -> 0.84079664 | L27: =(K27+K28+K29+K30+K31)*0.2 -> 0.86353539
A28: P40 | B28: SSF | C28: S82 | D28: S82,1 | E28: =Data_Scores!V28*0.33 -> 0.32600688 | F28: =Data_Scores!U28*0.33 -> 0.33 | G28: =Data_Scores!P28*0.33*0.33 -> 0.091458111 | H28: =Data_Scores!Q28*0.33*0.33 -> 0.099377742 | I28: =(Data_Scores!R28+Data_Scores!S28+Data_Scores!T28)*0.33*0.33*0.33 -> 0.056880612 | J28: =G28+H28+I28 -> 0.24771647 | K28: =E28+F28+J28 -> 0.90372334
A29: P60 | B29: SSF | C29: S82 | D29: S82,2 | E29: =Data_Scores!V29*0.33 -> 0.31862441 | F29: =Data_Scores!U29*0.33 -> 0.285 | G29: =Data_Scores!P29*0.33*0.33 -> 0.093443226 | H29: =Data_Scores!Q29*0.33*0.33 -> 0.10293006 | I29: =(Data_Scores!R29+Data_Scores!S29+Data_Scores!T29)*0.33*0.33*0.33 -> 0.04436488 | J29: =G29+H29+I29 -> 0.24073816 | K29: =E29+F29+J29 -> 0.84436257
A30: P80 | B30: SSF | C30: S82 | D30: S82,3 | E30: =Data_Scores!V30*0.33 -> 0.3213029 | F30: =Data_Scores!U30*0.33 -> 0.33 | G30: =Data_Scores!P30*0.33*0.33 -> 0.094190196 | H30: =Data_Scores!Q30*0.33*0.33 -> 0.052661088 | I30: =(Data_Scores!R30+Data_Scores!S30+Data_Scores!T30)*0.33*0.33*0.33 -> 0.047985243 | J30: =G30+H30+I30 -> 0.19483653 | K30: =E30+F30+J30 -> 0.84613943
A31: P100 | B31: SSF | C31: S82 | D31: S82,4 | E31: =Data_Scores!V31*0.33 -> 0.32455078 | F31: =Data_Scores!U31*0.33 -> 0.28959184 | G31: =Data_Scores!P31*0.33*0.33 -> 0.10612065 | H31: =Data_Scores!Q31*0.33*0.33 -> 0.10430783 | I31: =(Data_Scores!R31+Data_Scores!S31+Data_Scores!T31)*0.33*0.33*0.33 -> 0.058083851 | J31: =G31+H31+I31 -> 0.26851233 | K31: =E31+F31+J31 -> 0.88265495
A32: P20 | B32: DWS | C32: S101 | D32: S101 | E32: =Data_Scores!V32*0.33 -> 0.31291533 | F32: =Data_Scores!U32*0.33 -> 0.21914063 | G32: =Data_Scores!P32*0.33*0.33 -> 0.094278156 | H32: =Data_Scores!Q32*0.33*0.33 -> 0.064010959 | I32: =(Data_Scores!R32+Data_Scores!S32+Data_Scores!T32)*0.33*0.33*0.33 -> 0.05334688 | J32: =G32+H32+I32 -> 0.211636 | K32: =E32+F32+J32 -> 0.74369195 | L32: =(K32+K33+K34+K35+K36)*0.2 -> 0.79366099
A33: P40 | B33: DWS | C33: S101 | D33: S101,1 | E33: =Data_Scores!V33*0.33 -> 0.31443654 | F33: =Data_Scores!U33*0.33 -> 0.17368421 | G33: =Data_Scores!P33*0.33*0.33 -> 0.093023409 | H33: =Data_Scores!Q33*0.33*0.33 -> 0.081372019 | I33: =(Data_Scores!R33+Data_Scores!S33+Data_Scores!T33)*0.33*0.33*0.33 -> 0.061480745 | J33: =G33+H33+I33 -> 0.23587617 | K33: =E33+F33+J33 -> 0.72399693
A34: P60 | B34: DWS | C34: S101 | D34: S101,2 | E34: =Data_Scores!V34*0.33 -> 0.31995336 | F34: =Data_Scores!U34*0.33 -> 0.24 | G34: =Data_Scores!P34*0.33*0.33 -> 0.09438 | H34: =Data_Scores!Q34*0.33*0.33 -> 0.09160775 | I34: =(Data_Scores!R34+Data_Scores!S34+Data_Scores!T34)*0.33*0.33*0.33 -> 0.045267733 | J34: =G34+H34+I34 -> 0.23125548 | K34: =E34+F34+J34 -> 0.79120885
A35: P80 | B35: DWS | C35: S101 | D35: S101,3 | E35: =Data_Scores!V35*0.33 -> 0.32286841 | F35: =Data_Scores!U35*0.33 -> 0.30555556 | G35: =Data_Scores!P35*0.33*0.33 -> 0.095376471 | H35: =Data_Scores!Q35*0.33*0.33 -> 0.047853388 | I35: =(Data_Scores!R35+Data_Scores!S35+Data_Scores!T35)*0.33*0.33*0.33 -> 0.049439341 | J35: =G35+H35+I35 -> 0.1926692 | K35: =E35+F35+J35 -> 0.82109317
A36: P100 | B36: DWS | C36: S101 | D36: S101,4 | E36: =Data_Scores!V36*0.33 -> 0.32449709 | F36: =Data_Scores!U36*0.33 -> 0.28959184 | G36: =Data_Scores!P36*0.33*0.33 -> 0.10131995 | H36: =Data_Scores!Q36*0.33*0.33 -> 0.096654217 | I36: =(Data_Scores!R36+Data_Scores!S36+Data_Scores!T36)*0.33*0.33*0.33 -> 0.076250942 | J36: =G36+H36+I36 -> 0.27422511 | K36: =E36+F36+J36 -> 0.88831404
A37: P20 | B37: DWS | C37: S103 | D37: S103 | E37: =Data_Scores!V37*0.33 -> 0.32508698 | F37: =Data_Scores!U37*0.33 -> 0.22429688 | G37: =Data_Scores!P37*0.33*0.33 -> 0.085766934 | H37: =Data_Scores!Q37*0.33*0.33 -> 0.081505479 | I37: =(Data_Scores!R37+Data_Scores!S37+Data_Scores!T37)*0.33*0.33*0.33 -> 0.041515473 | J37: =G37+H37+I37 -> 0.20878789 | K37: =E37+F37+J37 -> 0.75817174 | L37: =(K37+K38+K39+K40+K41)*0.2 -> 0.76471692
A38: P40 | B38: DWS | C38: S103 | D38: S103,1 | E38: =Data_Scores!V38*0.33 -> 0.32689309 | F38: =Data_Scores!U38*0.33 -> 0.21710526 | G38: =Data_Scores!P38*0.33*0.33 -> 0.08743306 | H38: =Data_Scores!Q38*0.33*0.33 -> 0.1089 | I38: =(Data_Scores!R38+Data_Scores!S38+Data_Scores!T38)*0.33*0.33*0.33 -> 0.05818652 | J38: =G38+H38+I38 -> 0.25451958 | K38: =E38+F38+J38 -> 0.79851793
A39: P60 | B39: DWS | C39: S103 | D39: S103,2 | E39: =Data_Scores!V39*0.33 -> 0.32646136 | F39: =Data_Scores!U39*0.33 -> 0.22 | G39: =Data_Scores!P39*0.33*0.33 -> 0.091569677 | H39: =Data_Scores!Q39*0.33*0.33 -> 0.092019471 | I39: =(Data_Scores!R39+Data_Scores!S39+Data_Scores!T39)*0.33*0.33*0.33 -> 0.028901834 | J39: =G39+H39+I39 -> 0.21249098 | K39: =E39+F39+J39 -> 0.75895235
A40: P80 | B40: DWS | C40: S103 | D40: S103,3 | E40: =Data_Scores!V40*0.33 -> 0.33 | F40: =Data_Scores!U40*0.33 -> 0.25055556 | G40: =Data_Scores!P40*0.33*0.33 -> 0.092529412 | H40: =Data_Scores!Q40*0.33*0.33 -> 0.047853388 | I40: =(Data_Scores!R40+Data_Scores!S40+Data_Scores!T40)*0.33*0.33*0.33 -> 0.030899588 | J40: =G40+H40+I40 -> 0.17128239 | K40: =E40+F40+J40 -> 0.75183794
...

Sheet Legend
A1: Legend, Color Key & Formula Guide
A2: CORES — aba Data_Scores
A3: Fundo verde claro | B3: SSF — Seasonal Semideciduous Forest
A4: Fundo azul claro | B4: DWS — Densely Wooded Savanna
A5: Fundo salmão | B5: DA — Deforested Area
A6: Célula verde + texto branco negrito | B6: Maior valor na camada (variáveis: pH, CTC, N, P, SB, C)
A7: Célula laranja + texto branco negrito | B7: Menor BD na camada (menor densidade = melhor)
A8: Texto azul escuro (colunas score) | B8: Fórmula de normalização
A10: FÓRMULAS DE NORMALIZAÇÃO
A11: Mais é melhor (pH, CTC, N, P, SB, C) | B11: score = x / MAX(mesma camada) → maior valor recebe 1
A12: Menos é melhor (BD_Benites_2007) | B12: score = MIN(mesma camada) / x → menor valor recebe 1
A13: Exemplo score_pH (col P): | B13: =I4/SUMPRODUCT(MAX(($A$4:$A$148=A4)*$I$4:$I$148))
A14: Exemplo score_BD (col V): | B14: =SUMPRODUCT(MIN(IF($A$4:$A$148=A4,$O$4:$O$148,1E+99)))/O4
A15: Critério A4 (sem $): | B15: Relativo, ao copiar para baixo lê automaticamente a camada de cada linha
A17: PONDERAÇÃO — aba SHI_Results
A18: SHI_Physical | B18: =score_bd × 0.33
A19: SHI_Biological | B19: =score_c × 0.33
A20: SHI_Chem_pH | B20: =score_ph × 0.33 × 0.33
A21: SHI_Chem_CTC | B21: =score_ctc × 0.33 × 0.33
A22: SHI_Chem_Navail | B22: =(score_n + score_p + score_sb) × 0.33 × 0.33 × 0.33
A23: SHI_Chemical | B23: =shi_chem_ph + shi_chem_ctc + shi_chem_navail
A24: SHI_Layer | B24: =shi_physical + shi_biological + shi_chemical
A25: Overall_SHI | B25: =(shi_p20 + shi_p40 + shi_p60 + shi_p80 + shi_p100) × 0.20
A27: NOTA | B27: Perfil S51 (DWS) removido por ser outlier em BD, C, CTC e demais variáveis em P20
